Workbook

Sheet DESC
A1: CFS_national_values_degurba
A2: Created | B2: 21/06/2024
A3: Last Update | B3: 21/06/2025
A4: Authors | B4: Alessandra Carioli
A9: Input data
A11: GHSL R2023 data
A12: POP | B12: CIESIN GPW 4.1 census and gr - WPP2022 - WUP2018 | C12: Y:\01_GLOBAL\2020_Pop_estimates\ver_4\GHS-POP_production\Input_POP_layers_v1\CNTRY_layers.gdb
A13: BU for POP downscaling | B13: GHS-BUILT-V RES MT | C13: O:\01_GLOBAL\2020_Pop_estimates\ver_4\GHS-POP_production\BU4POP
A14: BU for SMOD classification | B14: GHS-BUILT-S TOT MT | C14: O:\01_GLOBAL\2022_GHS_SMOD\ver_4\BU1000
A15: POP grid | B15: 100m | C15: Y:\01_GLOBAL\2020_Pop_estimates\ver_4\GHS-POP_production\Processing\Global_mosaics\Pop_v1
B16: 1000m | C16: Y:\01_GLOBAL\2020_Pop_estimates\ver_4\GHS-POP_production\Processing\Global_mosaics\Pop_v1
A18: SMOD | B18: V1s7_O7_P2023_v2 | C18: O:\01_GLOBAL\2022_GHS_SMOD\ver_7\UCDBR2023_O7
A20: Countries/Territories | B20: GADM4.1 adapted for GHSL (disputed to admin) POPBU extend | C20: O:\01_GLOBAL\2022_GHS_SMOD\ver_4\GADM_extended\GADM41_POPBUextended_1000.tif
C21: O:\01_GLOBAL\2022_GHS_SMOD\ver_4\GADM_extended\GADM4104GHSL_CNTRY_map_v4.xlsx - Shortcut.lnk
A23: Sheets
A25: AREA_km2_L1 | B25: Percentage distribution Area (km2) by DEGURBA L1 per GADM4.1 country/territory
A26: POP_L1 | B26: Percentage distribution Pop by DEGURBA L1 per GADM4.1 country/territory
A27: BU_S_km2_L1 | B27: Percentage distribution Built-up surface (km2) by DEGURBA L1 per GADM4.1 country/territory
A28: BUCAP_m2_L1 | B28: Percentage distribution Built-up per capita (m2) by DEGURBA L1 per GADM4.1 country/territory
A30: Description
A32: AREA_km2_L1
A33: GADM_ID | B33: ID of GADM4.1 country or territory
A34: GADM_ISO | B34: ISO3 code of GADM4.1 country or territory
A35: GADM_NAME | B35: Name of GADM4.1 country or territory
A36: DEGURBA_L1 | B36: Stage 1 of DegUrba classes Urban Centre (UC), Urban Cluster (UCL), Rural Cluster (RUR)
A38: POP_L1
A39: GADM_ID | B39: ID of GADM4.1 country or territory
A40: GADM_ISO | B40: ISO3 code of GADM4.1 country or territory
A41: GADM_NAME | B41: Name of GADM4.1 country or territory
A42: DEGURBA_L1 | B42: Stage 1 of DegUrba classes Urban Centre (UC), Urban Cluster (UCL), Rural Cluster (RUR)
A44: BU_S_km2_L1
A45: GADM_ID | B45: ID of GADM4.1 country or territory
A46: GADM_ISO | B46: ISO3 code of GADM4.1 country or territory
A47: GADM_NAME | B47: Name of GADM4.1 country or territory
A48: DEGURBA_L1 | B48: Stage 1 of DegUrba classes Urban Centre (UC), Urban Cluster (UCL), Rural Cluster (RUR)
A50: BUCAP_m2_L1
A51: GADM_ID | B51: ID of GADM4.1 country or territory
A52: GADM_ISO | B52: ISO3 code of GADM4.1 country or territory
A53: GADM_NAME | B53: Name of GADM4.1 country or territory
A54: DEGURBA_L1 | B54: Stage 1 of DegUrba classes Urban Centre (UC), Urban Cluster (UCL), Rural Cluster (RUR)

Sheet AREA_KM2_L1
A1: GADM_ID | B1: GADM_ISO | C1: GADM_NAME | D1: DEGURBA_L1 | E1: 1975 | F1: 1980 | G1: 1985 | H1: 1990 | I1: 1995 | J1: 2000 | K1: 2005 | L1: 2010 | M1: 2015 | N1: 2020 | O1: 2025 | P1: 2030
A2: 1 | B2: ABW | C2: Aruba | D2: UC | E2: 0 | F2: 0 | G2: 0 | H2: 0 | I2: 0 | J2: 0 | K2: 0 | L2: 0 | M2: 0 | N2: 48 | O2: 48 | P2: 48
A3: 1 | B3: ABW | C3: Aruba | D3: UCL | E3: 66 | F3: 72 | G3: 76 | H3: 78 | I3: 85 | J3: 87 | K3: 89 | L3: 92 | M3: 97 | N3: 60 | O3: 60 | P3: 59
A4: 1 | B4: ABW | C4: Aruba | D4: RUR | E4: 161 | F4: 155 | G4: 151 | H4: 149 | I4: 142 | J4: 140 | K4: 138 | L4: 135 | M4: 130 | N4: 119 | O4: 119 | P4: 120
A5: 2 | B5: AFG | C5: Afghanistan | D5: UC | E5: 460 | F5: 479 | G5: 428 | H5: 425 | I5: 604 | J5: 737 | K5: 968 | L5: 1155 | M5: 1464 | N5: 1718 | O5: 2167 | P5: 2844
A6: 2 | B6: AFG | C6: Afghanistan | D6: UCL | E6: 3236 | F6: 3418 | G6: 2664 | H6: 2706 | I6: 4769 | J6: 5942 | K6: 7456 | L6: 8608 | M6: 10082 | N6: 11025 | O6: 11624 | P6: 11970
A7: 2 | B7: AFG | C7: Afghanistan | D7: RUR | E7: 641844 | F7: 641643 | G7: 642448 | H7: 642409 | I7: 640167 | J7: 638861 | K7: 637116 | L7: 635777 | M7: 633994 | N7: 632797 | O7: 631749 | P7: 630726
A8: 3 | B8: AGO | C8: Angola | D8: UC | E8: 317 | F8: 401 | G8: 516 | H8: 1103 | I8: 1208 | J8: 1412 | K8: 1584 | L8: 1872 | M8: 2212 | N8: 2409 | O8: 2529 | P8: 2652
A9: 3 | B9: AGO | C9: Angola | D9: UCL | E9: 876 | F9: 1085 | G9: 1415 | H9: 1311 | I9: 1558 | J9: 1739 | K9: 1932 | L9: 2002 | M9: 2147 | N9: 2427 | O9: 2934 | P9: 3299
A10: 3 | B10: AGO | C10: Angola | D10: RUR | E10: 1254659 | F10: 1254366 | G10: 1253921 | H10: 1253438 | I10: 1253086 | J10: 1252701 | K10: 1252336 | L10: 1251978 | M10: 1251493 | N10: 1251016 | O10: 1250389 | P10: 1249901
A11: 4 | B11: AIA | C11: Anguilla | D11: UC | E11: 0 | F11: 0 | G11: 0 | H11: 0 | I11: 0 | J11: 0 | K11: 0 | L11: 0 | M11: 0 | N11: 0 | O11: 0 | P11: 0
A12: 4 | B12: AIA | C12: Anguilla | D12: UCL | E12: 0 | F12: 0 | G12: 0 | H12: 0 | I12: 0 | J12: 0 | K12: 0 | L12: 0 | M12: 11 | N12: 11 | O12: 12 | P12: 13
A13: 4 | B13: AIA | C13: Anguilla | D13: RUR | E13: 141 | F13: 141 | G13: 141 | H13: 141 | I13: 141 | J13: 141 | K13: 141 | L13: 141 | M13: 130 | N13: 130 | O13: 129 | P13: 128
... A763: 254 | B763: ZWE | C763: Zimbabwe | D763: RUR | E763: 391303 | F763: 391106 | G763: 390831 | H763: 390643 | I763: 390487 | J763: 390366 | K763: 390273 | L763: 390182 | M763: 390017 | N763: 389753 | O763: 389501 | P763: 389291

Sheet POP_L1
A1: GADM_ID | B1: GADM_ISO | C1: GADM_NAME | D1: DEGURBA_L1 | E1: 1975 | F1: 1980 | G1: 1985 | H1: 1990 | I1: 1995 | J1: 2000 | K1: 2005 | L1: 2010 | M1: 2015 | N1: 2020 | O1: 2025 | P1: 2030
A2: 1 | B2: ABW | C2: Aruba | D2: UC | E2: 0 | F2: 0 | G2: 0 | H2: 0 | I2: 0 | J2: 0 | K2: 0 | L2: 0 | M2: 0 | N2: 56903.198 | O2: 58101.155 | P2: 58999.211
A3: 1 | B3: ABW | C3: Aruba | D3: UCL | E3: 52003.15 | F3: 54610.189 | G3: 57637.152 | H3: 58891.597 | I3: 71284.558 | J3: 83390.771 | K3: 88658.31 | L3: 94573.517 | M3: 99143.758 | N3: 45177.755 | O3: 43578.174 | P3: 41296.883
A4: 1 | B4: ABW | C4: Aruba | D4: RUR | E4: 8711.8499 | F4: 7656.811 | G4: 6840.8477 | H4: 6820.4031 | I4: 5765.4418 | J4: 5710.2292 | K4: 5824.6898 | L4: 5767.4828 | M4: 5113.2419 | N4: 4504.0474 | O4: 4363.6716 | P4: 4627.906
A5: 2 | B5: AFG | C5: Afghanistan | D5: UC | E5: 2835380.7 | F5: 2985645.9 | G5: 2623872 | H5: 2806825.3 | I5: 4399706.6 | J5: 5659209.8 | K5: 7774371.1 | L5: 9550691.4 | M5: 12301850 | N5: 15446552 | O5: 19349497 | P5: 24368339
A6: 2 | B6: AFG | C6: Afghanistan | D6: UCL | E6: 4693600.2 | F6: 4779604.4 | G6: 3566973.4 | H6: 3557222 | I6: 6650571 | J6: 8334396.7 | K6: 10705662 | L6: 12540384 | M6: 15329084 | N6: 17386015 | O6: 19044256 | P6: 19792979
A7: 2 | B7: AFG | C7: Afghanistan | D7: RUR | E7: 4656187.8 | F7: 4751596.6 | G7: 4357494.2 | H7: 4369940.6 | I7: 5403119.1 | J7: 5581389.3 | K7: 5956894.1 | L7: 6117843.7 | M7: 6129630.4 | N7: 6133350.5 | O7: 6100291.9 | P7: 6131415.8
A8: 3 | B8: AGO | C8: Angola | D8: UC | E8: 2812481.2 | F8: 3421875.9 | G8: 4285053.3 | H8: 5458780.2 | I8: 6553060.3 | J8: 8026731.2 | K8: 9926136 | L8: 12909944 | M8: 17058404 | N8: 21164204 | O8: 25186871 | P8: 29789718
A9: 3 | B9: AGO | C9: Angola | D9: UCL | E9: 1595670.9 | F9: 1897939 | G9: 2275353.7 | H9: 2438889.3 | I9: 2875724.8 | J9: 3169216 | K9: 3431488.9 | L9: 3670636.4 | M9: 3775713.2 | N9: 3967231.9 | O9: 4309905.6 | P9: 4628009.9
A10: 3 | B10: AGO | C10: Angola | D10: RUR | E10: 2625811.8 | F10: 3012043.9 | G10: 3412105.1 | H10: 3933779.1 | I10: 4487068.7 | J10: 5202565.5 | K10: 6097507.2 | L10: 6787527.2 | M10: 7297260.1 | N10: 8299262.9 | O10: 9445695.3 | P10: 10488464
A11: 4 | B11: AIA | C11: Anguilla | D11: UC | E11: 0 | F11: 0 | G11: 0 | H11: 0 | I11: 0 | J11: 0 | K11: 0 | L11: 0 | M11: 0 | N11: 0 | O11: 0 | P11: 0
A12: 4 | B12: AIA | C12: Anguilla | D12: UCL | E12: 0 | F12: 0 | G12: 0 | H12: 0 | I12: 0 | J12: 0 | K12: 0 | L12: 0 | M12: 5137.3088 | N12: 5164.7659 | O12: 5596.0417 | P12: 5833.9081
A13: 4 | B13: AIA | C13: Anguilla | D13: RUR | E13: 6463 | F13: 6560 | G13: 6907 | H13: 8316 | I13: 9601 | J13: 11047 | K13: 12128 | L13: 13172 | M13: 9387.6912 | N13: 10420.234 | O13: 10369.958 | P13: 10221.092
... A763: 254 | B763: ZWE | C763: Zimbabwe | D763: RUR | E763: 4074939.3 | F763: 4640857.8 | G763: 5590736 | H763: 6254192.5 | I763: 6596183.4 | J763: 7034603.7 | K763: 7269299.7 | L763: 7791643.1 | M763: 8877788.2 | N763: 10389847 | O763: 11703805 | P763: 12894353

Sheet BU_S_km2_L1
A1: GADM_ID | B1: GADM_ISO | C1: GADM_NAME | D1: DEGURBA_L1 | E1: 1975 | F1: 1980 | G1: 1985 | H1: 1990 | I1: 1995 | J1: 2000 | K1: 2005 | L1: 2010 | M1: 2015 | N1: 2020 | O1: 2025 | P1: 2030
A2: 1 | B2: ABW | C2: Aruba | D2: UC | E2: 0 | F2: 0 | G2: 0 | H2: 0 | I2: 0 | J2: 0 | K2: 0 | L2: 0 | M2: 0 | N2: 10.667812 | O2: 10.667812 | P2: 10.79797
A3: 1 | B3: ABW | C3: Aruba | D3: UCL | E3: 2.405075 | F3: 3.475035 | G3: 4.80705 | H3: 7.970153 | I3: 10.939677 | J3: 14.066022 | K3: 15.01572 | L3: 16.12561 | M3: 17.519232 | N3: 9.834384 | O3: 9.883761 | P3: 9.914438
A4: 1 | B4: ABW | C4: Aruba | D4: RUR | E4: 0.9043 | F4: 1.166425 | G4: 1.472834 | H4: 2.477374 | I4: 2.297479 | J4: 2.507467 | K4: 2.620803 | L4: 2.620734 | M4: 2.540497 | N4: 2.150662 | O4: 2.101285 | P4: 2.315257
A5: 2 | B5: AFG | C5: Afghanistan | D5: UC | E5: 59.696631 | F5: 65.429288 | G5: 68.15399 | H5: 72.247763 | I5: 97.190806 | J5: 115.59339 | K5: 139.06838 | L5: 166.92693 | M5: 203.37472 | N5: 230.50231 | O5: 254.60647 | P5: 290.4404
A6: 2 | B6: AFG | C6: Afghanistan | D6: UCL | E6: 65.550355 | F6: 75.258856 | G6: 80.243828 | H6: 97.190653 | I6: 121.11607 | J6: 143.10358 | K6: 164.34533 | L6: 188.30799 | M6: 220.70266 | N6: 272.35843 | O6: 296.77755 | P6: 291.04973
A7: 2 | B7: AFG | C7: Afghanistan | D7: RUR | E7: 75.625461 | F7: 84.199396 | G7: 110.36218 | H7: 129.95547 | I7: 107.27165 | J7: 101.40198 | K7: 94.141851 | L7: 95.418697 | M7: 94.708813 | N7: 102.53463 | O7: 99.434162 | P7: 97.06211
A8: 3 | B8: AGO | C8: Angola | D8: UC | E8: 57.914356 | F8: 73.266653 | G8: 93.450295 | H8: 291.75326 | I8: 314.37114 | J8: 357.41661 | K8: 384.96164 | L8: 440.86134 | M8: 506.71307 | N8: 592.68696 | O8: 605.628 | P8: 612.98482
A9: 3 | B9: AGO | C9: Angola | D9: UCL | E9: 62.906445 | F9: 102.93789 | G9: 194.06494 | H9: 89.982532 | I9: 108.88387 | J9: 122.94242 | K9: 137.81428 | L9: 131.33722 | M9: 135.73334 | N9: 179.01321 | O9: 199.40176 | P9: 208.46913
A10: 3 | B10: AGO | C10: Angola | D10: RUR | E10: 340.44324 | F10: 335.96014 | G10: 291.70658 | H10: 273.62365 | I10: 272.71962 | J10: 272.06824 | K10: 285.11248 | L10: 316.67612 | M10: 376.28786 | N10: 517.5136 | O10: 588.11327 | P10: 640.8738
A11: 4 | B11: AIA | C11: Anguilla | D11: UC | E11: 0 | F11: 0 | G11: 0 | H11: 0 | I11: 0 | J11: 0 | K11: 0 | L11: 0 | M11: 0 | N11: 0 | O11: 0 | P11: 0
A12: 4 | B12: AIA | C12: Anguilla | D12: UCL | E12: 0 | F12: 0 | G12: 0 | H12: 0 | I12: 0 | J12: 0 | K12: 0 | L12: 0 | M12: 1.002056 | N12: 1.219746 | O12: 1.310068 | P12: 1.438021
A13: 4 | B13: AIA | C13: Anguilla | D13: RUR | E13: 1.106356 | F13: 1.546545 | G13: 2.250718 | H13: 3.111041 | I13: 3.147782 | J13: 3.198374 | K13: 3.262597 | L13: 3.3377 | M13: 2.618523 | N13: 3.557508 | O13: 3.467186 | P13: 3.528141
... A763: 254 | B763: ZWE | C763: Zimbabwe | D763: RUR | E763: 145.22489 | F763: 168.5414 | G763: 197.5795 | H763: 230.22579 | I763: 248.97552 | J763: 283.45746 | K763: 339.12109 | L763: 450.35236 | M763: 633.92793 | N763: 993.96438 | O763: 1237.308 | P763: 1389.652

Sheet BUCAP_m2_L1
A1: GADM_ID | B1: GADM_ISO | C1: GADM_NAME | D1: DEGURBA_L1 | E1: 1975 | F1: 1980 | G1: 1985 | H1: 1990 | I1: 1995 | J1: 2000 | K1: 2005 | L1: 2010 | M1: 2015 | N1: 2020 | O1: 2025 | P1: 2030
A2: 1 | B2: ABW | C2: Aruba | D2: UC | E2: - | F2: - | G2: - | H2: - | I2: - | J2: - | K2: - | L2: - | M2: - | N2: =BU_S_km2_L1!N2/POP_L1!N2*1000000 -> 187.47298 | O2: =BU_S_km2_L1!O2/POP_L1!O2*1000000 -> 183.60757 | P2: =BU_S_km2_L1!P2/POP_L1!P2*1000000 -> 183.01889
A3: 1 | B3: ABW | C3: Aruba | D3: UCL | E3: =BU_S_km2_L1!E3/POP_L1!E3*1000000 -> 46.248641 | F3: =BU_S_km2_L1!F3/POP_L1!F3*1000000 -> 63.633455 | G3: =BU_S_km2_L1!G3/POP_L1!G3*1000000 -> 83.401935 | H3: =BU_S_km2_L1!H3/POP_L1!H3*1000000 -> 135.336 | I3: =BU_S_km2_L1!I3/POP_L1!I3*1000000 -> 153.46489 | J3: =BU_S_km2_L1!J3/POP_L1!J3*1000000 -> 168.676 | K3: =BU_S_km2_L1!K3/POP_L1!K3*1000000 -> 169.36619 | L3: =BU_S_km2_L1!L3/POP_L1!L3*1000000 -> 170.50873 | ... P3: =BU_S_km2_L1!P3/POP_L1!P3*1000000 -> 240.07715
A4: 1 | B4: ABW | C4: Aruba | D4: RUR | E4: =BU_S_km2_L1!E4/POP_L1!E4*1000000 -> 103.80115 | F4: =BU_S_km2_L1!F4/POP_L1!F4*1000000 -> 152.33823 | G4: =BU_S_km2_L1!G4/POP_L1!G4*1000000 -> 215.29992 | H4: =BU_S_km2_L1!H4/POP_L1!H4*1000000 -> 363.22985 | I4: =BU_S_km2_L1!I4/POP_L1!I4*1000000 -> 398.4914 | J4: =BU_S_km2_L1!J4/POP_L1!J4*1000000 -> 439.11845 | K4: =BU_S_km2_L1!K4/POP_L1!K4*1000000 -> 449.94722 | L4: =BU_S_km2_L1!L4/POP_L1!L4*1000000 -> 454.39823 | ... P4: =BU_S_km2_L1!P4/POP_L1!P4*1000000 -> 500.28177
A5: 2 | B5: AFG | C5: Afghanistan | D5: UC | E5: =BU_S_km2_L1!E5/POP_L1!E5*1000000 -> 21.054186 | F5: =BU_S_km2_L1!F5/POP_L1!F5*1000000 -> 21.914618 | G5: =BU_S_km2_L1!G5/POP_L1!G5*1000000 -> 25.974587 | H5: =BU_S_km2_L1!H5/POP_L1!H5*1000000 -> 25.740029 | I5: =BU_S_km2_L1!I5/POP_L1!I5*1000000 -> 22.090292 | J5: =BU_S_km2_L1!J5/POP_L1!J5*1000000 -> 20.425712 | K5: =BU_S_km2_L1!K5/POP_L1!K5*1000000 -> 17.888056 | L5: =BU_S_km2_L1!L5/POP_L1!L5*1000000 -> 17.477994 | ... P5: =BU_S_km2_L1!P5/POP_L1!P5*1000000 -> 11.918761
A6: 2 | B6: AFG | C6: Afghanistan | D6: UCL | E6: =BU_S_km2_L1!E6/POP_L1!E6*1000000 -> 13.965901 | F6: =BU_S_km2_L1!F6/POP_L1!F6*1000000 -> 15.745834 | G6: =BU_S_km2_L1!G6/POP_L1!G6*1000000 -> 22.496335 | H6: =BU_S_km2_L1!H6/POP_L1!H6*1000000 -> 27.322066 | I6: =BU_S_km2_L1!I6/POP_L1!I6*1000000 -> 18.21138 | J6: =BU_S_km2_L1!J6/POP_L1!J6*1000000 -> 17.170239 | K6: =BU_S_km2_L1!K6/POP_L1!K6*1000000 -> 15.351253 | L6: =BU_S_km2_L1!L6/POP_L1!L6*1000000 -> 15.016127 | ... P6: =BU_S_km2_L1!P6/POP_L1!P6*1000000 -> 14.704695
A7: 2 | B7: AFG | C7: Afghanistan | D7: RUR | E7: =BU_S_km2_L1!E7/POP_L1!E7*1000000 -> 16.241927 | F7: =BU_S_km2_L1!F7/POP_L1!F7*1000000 -> 17.720232 | G7: =BU_S_km2_L1!G7/POP_L1!G7*1000000 -> 25.326983 | H7: =BU_S_km2_L1!H7/POP_L1!H7*1000000 -> 29.738498 | I7: =BU_S_km2_L1!I7/POP_L1!I7*1000000 -> 19.853652 | J7: =BU_S_km2_L1!J7/POP_L1!J7*1000000 -> 18.167875 | K7: =BU_S_km2_L1!K7/POP_L1!K7*1000000 -> 15.803848 | L7: =BU_S_km2_L1!L7/POP_L1!L7*1000000 -> 15.596786 | ... P7: =BU_S_km2_L1!P7/POP_L1!P7*1000000 -> 15.830293
A8: 3 | B8: AGO | C8: Angola | D8: UC | E8: =BU_S_km2_L1!E8/POP_L1!E8*1000000 -> 20.591909 | F8: =BU_S_km2_L1!F8/POP_L1!F8*1000000 -> 21.411254 | G8: =BU_S_km2_L1!G8/POP_L1!G8*1000000 -> 21.808433 | H8: =BU_S_km2_L1!H8/POP_L1!H8*1000000 -> 53.446604 | I8: =BU_S_km2_L1!I8/POP_L1!I8*1000000 -> 47.97318 | J8: =BU_S_km2_L1!J8/POP_L1!J8*1000000 -> 44.52829 | K8: =BU_S_km2_L1!K8/POP_L1!K8*1000000 -> 38.782628 | L8: =BU_S_km2_L1!L8/POP_L1!L8*1000000 -> 34.148975 | ... P8: =BU_S_km2_L1!P8/POP_L1!P8*1000000 -> 20.57706
A9: 3 | B9: AGO | C9: Angola | D9: UCL | E9: =BU_S_km2_L1!E9/POP_L1!E9*1000000 -> 39.423194 | F9: =BU_S_km2_L1!F9/POP_L1!F9*1000000 -> 54.236666 | G9: =BU_S_km2_L1!G9/POP_L1!G9*1000000 -> 85.290009 | H9: =BU_S_km2_L1!H9/POP_L1!H9*1000000 -> 36.894881 | I9: =BU_S_km2_L1!I9/POP_L1!I9*1000000 -> 37.863106 | J9: =BU_S_km2_L1!J9/POP_L1!J9*1000000 -> 38.792692 | K9: =BU_S_km2_L1!K9/POP_L1!K9*1000000 -> 40.161658 | L9: =BU_S_km2_L1!L9/POP_L1!L9*1000000 -> 35.780503 | ... P9: =BU_S_km2_L1!P9/POP_L1!P9*1000000 -> 45.045091
A10: 3 | B10: AGO | C10: Angola | D10: RUR | E10: =BU_S_km2_L1!E10/POP_L1!E10*1000000 -> 129.65256 | F10: =BU_S_km2_L1!F10/POP_L1!F10*1000000 -> 111.53892 | G10: =BU_S_km2_L1!G10/POP_L1!G10*1000000 -> 85.491674 | H10: =BU_S_km2_L1!H10/POP_L1!H10*1000000 -> 69.557452 | I10: =BU_S_km2_L1!I10/POP_L1!I10*1000000 -> 60.779016 | J10: =BU_S_km2_L1!J10/POP_L1!J10*1000000 -> 52.295015 | K10: =BU_S_km2_L1!K10/POP_L1!K10*1000000 -> 46.75886 | L10: =BU_S_km2_L1!L10/POP_L1!L10*1000000 -> 46.655595 | ... P10: =BU_S_km2_L1!P10/POP_L1!P10*1000000 -> 61.10273
A11: 4 | B11: AIA | C11: Anguilla | D11: UC | E11: - | F11: - | G11: - | H11: - | I11: - | J11: - | K11: - | L11: - | M11: - | N11: - | O11: - | P11: -
A12: 4 | B12: AIA | C12: Anguilla | D12: UCL | E12: - | F12: - | G12: - | H12: - | I12: - | J12: - | K12: - | L12: - | M12: =BU_S_km2_L1!M12/POP_L1!M12*1000000 -> 195.05466 | N12: =BU_S_km2_L1!N12/POP_L1!N12*1000000 -> 236.16676 | O12: =BU_S_km2_L1!O12/POP_L1!O12*1000000 -> 234.10619 | P12: =BU_S_km2_L1!P12/POP_L1!P12*1000000 -> 246.4936
A13: 4 | B13: AIA | C13: Anguilla | D13: RUR | E13: =BU_S_km2_L1!E13/POP_L1!E13*1000000 -> 171.18304 | F13: =BU_S_km2_L1!F13/POP_L1!F13*1000000 -> 235.75381 | G13: =BU_S_km2_L1!G13/POP_L1!G13*1000000 -> 325.86043 | H13: =BU_S_km2_L1!H13/POP_L1!H13*1000000 -> 374.10305 | I13: =BU_S_km2_L1!I13/POP_L1!I13*1000000 -> 327.85981 | J13: =BU_S_km2_L1!J13/POP_L1!J13*1000000 -> 289.52421 | K13: =BU_S_km2_L1!K13/POP_L1!K13*1000000 -> 269.0136 | L13: =BU_S_km2_L1!L13/POP_L1!L13*1000000 -> 253.39356 | ... P13: =BU_S_km2_L1!P13/POP_L1!P13*1000000 -> 345.1824
A14: 5 | B14: ALA | C14: Aland | D14: UC | E14: - | F14: - | G14: - | H14: - | I14: - | J14: - | K14: - | L14: - | M14: - | N14: - | O14: - | P14: -
A15: 5 | B15: ALA | C15: Aland | D15: UCL | E15: =BU_S_km2_L1!E15/POP_L1!E15*1000000 -> 48.943254 | F15: =BU_S_km2_L1!F15/POP_L1!F15*1000000 -> 52.167626 | G15: =BU_S_km2_L1!G15/POP_L1!G15*1000000 -> 54.07085 | H15: =BU_S_km2_L1!H15/POP_L1!H15*1000000 -> 58.163747 | I15: =BU_S_km2_L1!I15/POP_L1!I15*1000000 -> 66.137506 | J15: =BU_S_km2_L1!J15/POP_L1!J15*1000000 -> 75.420971 | K15: =BU_S_km2_L1!K15/POP_L1!K15*1000000 -> 83.177705 | L15: =BU_S_km2_L1!L15/POP_L1!L15*1000000 -> 89.44645 | ... P15: =BU_S_km2_L1!P15/POP_L1!P15*1000000 -> 97.78008
A16: 5 | B16: ALA | C16: Aland | D16: RUR | E16: =BU_S_km2_L1!E16/POP_L1!E16*1000000 -> 84.817782 | F16: =BU_S_km2_L1!F16/POP_L1!F16*1000000 -> 89.666214 | G16: =BU_S_km2_L1!G16/POP_L1!G16*1000000 -> 92.226592 | H16: =BU_S_km2_L1!H16/POP_L1!H16*1000000 -> 98.388149 | I16: =BU_S_km2_L1!I16/POP_L1!I16*1000000 -> 100.8498 | J16: =BU_S_km2_L1!J16/POP_L1!J16*1000000 -> 105.0955 | K16: =BU_S_km2_L1!K16/POP_L1!K16*1000000 -> 105.90527 | L16: =BU_S_km2_L1!L16/POP_L1!L16*1000000 -> 105.45912 | ... P16: =BU_S_km2_L1!P16/POP_L1!P16*1000000 -> 107.29815
A17: 6 | B17: ALB | C17: Albania | D17: UC | E17: =BU_S_km2_L1!E17/POP_L1!E17*1000000 -> 6.4444108 | F17: =BU_S_km2_L1!F17/POP_L1!F17*1000000 -> 13.664787 | G17: =BU_S_km2_L1!G17/POP_L1!G17*1000000 -> 25.862054 | H17: =BU_S_km2_L1!H17/POP_L1!H17*1000000 -> 25.251006 | I17: =BU_S_km2_L1!I17/POP_L1!I17*1000000 -> 28.775859 | J17: =BU_S_km2_L1!J17/POP_L1!J17*1000000 -> 32.88449 | K17: =BU_S_km2_L1!K17/POP_L1!K17*1000000 -> 33.501241 | L17: =BU_S_km2_L1!L17/POP_L1!L17*1000000 -> 34.505482 | ... P17: =BU_S_km2_L1!P17/POP_L1!P17*1000000 -> 28.607968
A18: 6 | B18: ALB | C18: Albania | D18: UCL | E18: =BU_S_km2_L1!E18/POP_L1!E18*1000000 -> 30.427705 | F18: =BU_S_km2_L1!F18/POP_L1!F18*1000000 -> 31.119142 | G18: =BU_S_km2_L1!G18/POP_L1!G18*1000000 -> 29.37822 | H18: =BU_S_km2_L1!H18/POP_L1!H18*1000000 -> 33.262858 | I18: =BU_S_km2_L1!I18/POP_L1!I18*1000000 -> 42.466524 | J18: =BU_S_km2_L1!J18/POP_L1!J18*1000000 -> 51.560576 | K18: =BU_S_km2_L1!K18/POP_L1!K18*1000000 -> 60.907306 | L18: =BU_S_km2_L1!L18/POP_L1!L18*1000000 -> 70.201228 | ... P18: =BU_S_km2_L1!P18/POP_L1!P18*1000000 -> 93.884693
A19: 6 | B19: ALB | C19: Albania | D19: RUR | E19: =BU_S_km2_L1!E19/POP_L1!E19*1000000 -> 57.23028 | F19: =BU_S_km2_L1!F19/POP_L1!F19*1000000 -> 50.606113 | G19: =BU_S_km2_L1!G19/POP_L1!G19*1000000 -> 48.830352 | H19: =BU_S_km2_L1!H19/POP_L1!H19*1000000 -> 50.299177 | I19: =BU_S_km2_L1!I19/POP_L1!I19*1000000 -> 56.639309 | J19: =BU_S_km2_L1!J19/POP_L1!J19*1000000 -> 67.259979 | K19: =BU_S_km2_L1!K19/POP_L1!K19*1000000 -> 84.750734 | L19: =BU_S_km2_L1!L19/POP_L1!L19*1000000 -> 105.40803 | ... P19: =BU_S_km2_L1!P19/POP_L1!P19*1000000 -> 217.76257
A20: 7 | B20: AND | C20: Andorra | D20: UC | E20: - | F20: - | G20: - | H20: - | I20: - | J20: - | K20: - | L20: - | M20: - | N20: - | O20: - | P20: -
A21: 7 | B21: AND | C21: Andorra | D21: UCL | E21: =BU_S_km2_L1!E21/POP_L1!E21*1000000 -> 14.225276 | F21: =BU_S_km2_L1!F21/POP_L1!F21*1000000 -> 12.939225 | G21: =BU_S_km2_L1!G21/POP_L1!G21*1000000 -> 13.70785 | H21: =BU_S_km2_L1!H21/POP_L1!H21*1000000 -> 13.711101 | I21: =BU_S_km2_L1!I21/POP_L1!I21*1000000 -> 14.566134 | J21: =BU_S_km2_L1!J21/POP_L1!J21*1000000 -> 17.246094 | K21: =BU_S_km2_L1!K21/POP_L1!K21*1000000 -> 18.60946 | L21: =BU_S_km2_L1!L21/POP_L1!L21*1000000 -> 22.762121 | ... P21: =BU_S_km2_L1!P21/POP_L1!P21*1000000 -> 28.70917
A22: 7 | B22: AND | C22: Andorra | D22: RUR | E22: =BU_S_km2_L1!E22/POP_L1!E22*1000000 -> 73.046602 | F22: =BU_S_km2_L1!F22/POP_L1!F22*1000000 -> 65.022744 | G22: =BU_S_km2_L1!G22/POP_L1!G22*1000000 -> 56.846529 | H22: =BU_S_km2_L1!H22/POP_L1!H22*1000000 -> 62.061883 | I22: =BU_S_km2_L1!I22/POP_L1!I22*1000000 -> 51.602781 | J22: =BU_S_km2_L1!J22/POP_L1!J22*1000000 -> 49.641843 | K22: =BU_S_km2_L1!K22/POP_L1!K22*1000000 -> 40.181344 | L22: =BU_S_km2_L1!L22/POP_L1!L22*1000000 -> 44.906062 | ... P22: =BU_S_km2_L1!P22/POP_L1!P22*1000000 -> 33.903078
A23: 8 | B23: ARE | C23: United Arab Emirates | D23: UC | E23: =BU_S_km2_L1!E23/POP_L1!E23*1000000 -> 254.11432 | F23: =BU_S_km2_L1!F23/POP_L1!F23*1000000 -> 121.67935 | G23: =BU_S_km2_L1!G23/POP_L1!G23*1000000 -> 97.494796 | H23: =BU_S_km2_L1!H23/POP_L1!H23*1000000 -> 82.334097 | I23: =BU_S_km2_L1!I23/POP_L1!I23*1000000 -> 88.837817 | J23: =BU_S_km2_L1!J23/POP_L1!J23*1000000 -> 90.776177 | K23: =BU_S_km2_L1!K23/POP_L1!K23*1000000 -> 73.963621 | L23: =BU_S_km2_L1!L23/POP_L1!L23*1000000 -> 45.949765 | ... P23: =BU_S_km2_L1!P23/POP_L1!P23*1000000 -> 47.581412
A24: 8 | B24: ARE | C24: United Arab Emirates | D24: UCL | E24: =BU_S_km2_L1!E24/POP_L1!E24*1000000 -> 223.86911 | F24: =BU_S_km2_L1!F24/POP_L1!F24*1000000 -> 184.03781 | G24: =BU_S_km2_L1!G24/POP_L1!G24*1000000 -> 160.36537 | H24: =BU_S_km2_L1!H24/POP_L1!H24*1000000 -> 144.49307 | I24: =BU_S_km2_L1!I24/POP_L1!I24*1000000 -> 129.7482 | J24: =BU_S_km2_L1!J24/POP_L1!J24*1000000 -> 119.95051 | K24: =BU_S_km2_L1!K24/POP_L1!K24*1000000 -> 108.71973 | L24: =BU_S_km2_L1!L24/POP_L1!L24*1000000 -> 66.661008 | ... P24: =BU_S_km2_L1!P24/POP_L1!P24*1000000 -> 102.27686
A25: 8 | B25: ARE | C25: United Arab Emirates | D25: RUR | E25: =BU_S_km2_L1!E25/POP_L1!E25*1000000 -> 530.64763 | F25: =BU_S_km2_L1!F25/POP_L1!F25*1000000 -> 357.51471 | G25: =BU_S_km2_L1!G25/POP_L1!G25*1000000 -> 313.78016 | H25: =BU_S_km2_L1!H25/POP_L1!H25*1000000 -> 285.13762 | I25: =BU_S_km2_L1!I25/POP_L1!I25*1000000 -> 263.03722 | J25: =BU_S_km2_L1!J25/POP_L1!J25*1000000 -> 262.86381 | K25: =BU_S_km2_L1!K25/POP_L1!K25*1000000 -> 231.86169 | L25: =BU_S_km2_L1!L25/POP_L1!L25*1000000 -> 127.57163 | ... P25: =BU_S_km2_L1!P25/POP_L1!P25*1000000 -> 178.44792
A26: 9 | B26: ARG | C26: Argentina | D26: UC | E26: =BU_S_km2_L1!E26/POP_L1!E26*1000000 -> 56.700948 | F26: =BU_S_km2_L1!F26/POP_L1!F26*1000000 -> 54.315967 | G26: =BU_S_km2_L1!G26/POP_L1!G26*1000000 -> 52.980351 | H26: =BU_S_km2_L1!H26/POP_L1!H26*1000000 -> 51.728247 | I26: =BU_S_km2_L1!I26/POP_L1!I26*1000000 -> 53.749247 | J26: =BU_S_km2_L1!J26/POP_L1!J26*1000000 -> 56.004254 | K26: =BU_S_km2_L1!K26/POP_L1!K26*1000000 -> 56.099443 | L26: =BU_S_km2_L1!L26/POP_L1!L26*1000000 -> 56.184549 | ... P26: =BU_S_km2_L1!P26/POP_L1!P26*1000000 -> 54.746439
A27: 9 | B27: ARG | C27: Argentina | D27: UCL | E27: =BU_S_km2_L1!E27/POP_L1!E27*1000000 -> 85.915391 | F27: =BU_S_km2_L1!F27/POP_L1!F27*1000000 -> 86.24599 | G27: =BU_S_km2_L1!G27/POP_L1!G27*1000000 -> 85.674289 | H27: =BU_S_km2_L1!H27/POP_L1!H27*1000000 -> 84.986487 | I27: =BU_S_km2_L1!I27/POP_L1!I27*1000000 -> 89.670802 | J27: =BU_S_km2_L1!J27/POP_L1!J27*1000000 -> 94.703408 | K27: =BU_S_km2_L1!K27/POP_L1!K27*1000000 -> 97.920029 | L27: =BU_S_km2_L1!L27/POP_L1!L27*1000000 -> 101.39353 | ... P27: =BU_S_km2_L1!P27/POP_L1!P27*1000000 -> 103.16396
A28: 9 | B28: ARG | C28: Argentina | D28: RUR | E28: =BU_S_km2_L1!E28/POP_L1!E28*1000000 -> 170.96774 | F28: =BU_S_km2_L1!F28/POP_L1!F28*1000000 -> 175.45654 | G28: =BU_S_km2_L1!G28/POP_L1!G28*1000000 -> 175.51306 | H28: =BU_S_km2_L1!H28/POP_L1!H28*1000000 -> 176.63106 | I28: =BU_S_km2_L1!I28/POP_L1!I28*1000000 -> 182.77334 | J28: =BU_S_km2_L1!J28/POP_L1!J28*1000000 -> 190.02551 | K28: =BU_S_km2_L1!K28/POP_L1!K28*1000000 -> 193.40474 | L28: =BU_S_km2_L1!L28/POP_L1!L28*1000000 -> 198.75324 | ... P28: =BU_S_km2_L1!P28/POP_L1!P28*1000000 -> 197.88791
A29: 10 | B29: ARM | C29: Armenia | D29: UC | E29: =BU_S_km2_L1!E29/POP_L1!E29*1000000 -> 30.999594 | F29: =BU_S_km2_L1!F29/POP_L1!F29*1000000 -> 29.180239 | G29: =BU_S_km2_L1!G29/POP_L1!G29*1000000 -> 30.112969 | H29: =BU_S_km2_L1!H29/POP_L1!H29*1000000 -> 30.522323 | I29: =BU_S_km2_L1!I29/POP_L1!I29*1000000 -> 33.780617 | J29: =BU_S_km2_L1!J29/POP_L1!J29*1000000 -> 37.255838 | K29: =BU_S_km2_L1!K29/POP_L1!K29*1000000 -> 39.633852 | L29: =BU_S_km2_L1!L29/POP_L1!L29*1000000 -> 42.627477 | ... P29: =BU_S_km2_L1!P29/POP_L1!P29*1000000 -> 48.964751
A30: 10 | B30: ARM | C30: Armenia | D30: UCL | E30: =BU_S_km2_L1!E30/POP_L1!E30*1000000 -> 54.996823 | F30: =BU_S_km2_L1!F30/POP_L1!F30*1000000 -> 53.263432 | G30: =BU_S_km2_L1!G30/POP_L1!G30*1000000 -> 51.226275 | H30: =BU_S_km2_L1!H30/POP_L1!H30*1000000 -> 48.443515 | I30: =BU_S_km2_L1!I30/POP_L1!I30*1000000 -> 57.283314 | J30: =BU_S_km2_L1!J30/POP_L1!J30*1000000 -> 65.179964 | K30: =BU_S_km2_L1!K30/POP_L1!K30*1000000 -> 72.537256 | L30: =BU_S_km2_L1!L30/POP_L1!L30*1000000 -> 78.891321 | ... P30: =BU_S_km2_L1!P30/POP_L1!P30*1000000 -> 89.001664
A31: 10 | B31: ARM | C31: Armenia | D31: RUR | E31: =BU_S_km2_L1!E31/POP_L1!E31*1000000 -> 71.1937 | F31: =BU_S_km2_L1!F31/POP_L1!F31*1000000 -> 68.070898 | G31: =BU_S_km2_L1!G31/POP_L1!G31*1000000 -> 67.098254 | H31: =BU_S_km2_L1!H31/POP_L1!H31*1000000 -> 62.876489 | I31: =BU_S_km2_L1!I31/POP_L1!I31*1000000 -> 74.559982 | J31: =BU_S_km2_L1!J31/POP_L1!J31*1000000 -> 85.312136 | K31: =BU_S_km2_L1!K31/POP_L1!K31*1000000 -> 96.380555 | L31: =BU_S_km2_L1!L31/POP_L1!L31*1000000 -> 107.82571 | ... P31: =BU_S_km2_L1!P31/POP_L1!P31*1000000 -> 132.56414
A32: 11 | B32: ASM | C32: American Samoa | D32: UC | E32: - | F32: - | G32: - | H32: - | I32: - | J32: - | K32: - | L32: - | M32: - | N32: - | O32: - | P32: -
A33: 11 | B33: ASM | C33: American Samoa | D33: UCL | E33: =BU_S_km2_L1!E33/POP_L1!E33*1000000 -> 69.970786 | F33: =BU_S_km2_L1!F33/POP_L1!F33*1000000 -> 76.892357 | G33: =BU_S_km2_L1!G33/POP_L1!G33*1000000 -> 75.048804 | H33: =BU_S_km2_L1!H33/POP_L1!H33*1000000 -> 76.029977 | I33: =BU_S_km2_L1!I33/POP_L1!I33*1000000 -> 72.499044 | J33: =BU_S_km2_L1!J33/POP_L1!J33*1000000 -> 69.233142 | K33: =BU_S_km2_L1!K33/POP_L1!K33*1000000 -> 72.986964 | L33: =BU_S_km2_L1!L33/POP_L1!L33*1000000 -> 80.240175 | ... P33: =BU_S_km2_L1!P33/POP_L1!P33*1000000 -> 116.84348
A34: 11 | B34: ASM | C34: American Samoa | D34: RUR | E34: =BU_S_km2_L1!E34/POP_L1!E34*1000000 -> 85.993268 | F34: =BU_S_km2_L1!F34/POP_L1!F34*1000000 -> 94.698015 | G34: =BU_S_km2_L1!G34/POP_L1!G34*1000000 -> 98.473553 | H34: =BU_S_km2_L1!H34/POP_L1!H34*1000000 -> 90.524215 | I34: =BU_S_km2_L1!I34/POP_L1!I34*1000000 -> 80.698921 | J34: =BU_S_km2_L1!J34/POP_L1!J34*1000000 -> 77.850399 | K34: =BU_S_km2_L1!K34/POP_L1!K34*1000000 -> 81.081463 | L34: =BU_S_km2_L1!L34/POP_L1!L34*1000000 -> 81.10153 | ... P34: =BU_S_km2_L1!P34/POP_L1!P34*1000000 -> 104.97828
A35: 12 | B35: ATA | C35: Antarctica | D35: UC | E35: - | F35: - | G35: - | H35: - | I35: - | J35: - | K35: - | L35: - | M35: - | N35: - | O35: - | P35: -
A36: 12 | B36: ATA | C36: Antarctica | D36: UCL | E36: - | F36: - | G36: - | H36: - | I36: - | J36: - | K36: - | L36: - | M36: - | N36: - | O36: - | P36: -
A37: 12 | B37: ATA | C37: Antarctica | D37: RUR | E37: - | F37: - | G37: - | H37: - | I37: - | J37: - | K37: - | L37: - | M37: - | N37: - | O37: - | P37: -
A38: 13 | B38: ATF | C38: French Southern Territories | D38: UC | E38: - | F38: - | G38: - | H38: - | I38: - | J38: - | K38: - | L38: - | M38: - | N38: - | O38: - | P38: -
A39: 13 | B39: ATF | C39: French Southern Territories | D39: UCL | E39: - | F39: - | G39: - | H39: - | I39: - | J39: - | K39: - | L39: - | M39: - | N39: - | O39: - | P39: -
A40: 13 | B40: ATF | C40: French Southern Territories | D40: RUR | E40: - | F40: - | G40: - | H40: - | I40: - | J40: - | K40: - | L40: - | M40: - | N40: - | O40: - | P40: -
...
